{"uuid": "29f1e3fc-17b4-4fc4-8542-8c0f18d8ee22", "children": ["445c223f-25e1-47e3-b5ed-59767ec77214", "9c13da55-3908-4567-ba3a-c55834a2602a", "8af4008d-10b3-42ad-baad-e5f5f90d2f4b", "08dce9bc-f2e9-419f-a9b3-62d66e258d04", "b52f6a3c-6e31-464e-868e-d0c5ed6099ad", "e430294a-90bd-4400-b4b3-ba71c8fc7d63", "e67bde8e-c425-48d7-9172-70293cb6bd01"], "befores": [{"name": "driver", "status": "broken", "statusDetails": {"message": "urllib3.exceptions.MaxRetryError: HTTPConnectionPool(host='127.0.0.1', port=4723): Max retries exceeded with url: /wd/hub/session (Caused by NewConnectionError('<urllib3.connection.HTTPConnection object at 0x00000215E4996CC8>: Failed to establish a new connection: [WinError 10061] 由于目标计算机积极拒绝，无法连接。'))\n", "trace": "  File \"d:\\python37\\lib\\site-packages\\pluggy\\callers.py\", line 187, in _multicall\n    res = hook_impl.function(*args)\n  File \"d:\\python37\\lib\\site-packages\\_pytest\\fixtures.py\", line 958, in pytest_fixture_setup\n    result = call_fixture_func(fixturefunc, request, kwargs)\n  File \"d:\\python37\\lib\\site-packages\\_pytest\\fixtures.py\", line 784, in call_fixture_func\n    res = next(it)\n  File \"D:\\Atest_project\\appium_pytest_tea7\\test_case\\conftest.py\", line 38, in driver\n    driver = webdriver.Remote('http://' + str(data['ip']) + ':' + str(data['port']) + '/wd/hub', desired_caps)\n  File \"d:\\python37\\lib\\site-packages\\appium\\webdriver\\webdriver.py\", line 151, in __init__\n    proxy\n  File \"d:\\python37\\lib\\site-packages\\selenium\\webdriver\\remote\\webdriver.py\", line 157, in __init__\n    self.start_session(capabilities, browser_profile)\n  File \"d:\\python37\\lib\\site-packages\\appium\\webdriver\\webdriver.py\", line 227, in start_session\n    response = self.execute(RemoteCommand.NEW_SESSION, parameters)\n  File \"d:\\python37\\lib\\site-packages\\selenium\\webdriver\\remote\\webdriver.py\", line 319, in execute\n    response = self.command_executor.execute(driver_command, params)\n  File \"d:\\python37\\lib\\site-packages\\selenium\\webdriver\\remote\\remote_connection.py\", line 374, in execute\n    return self._request(command_info[0], url, body=data)\n  File \"d:\\python37\\lib\\site-packages\\selenium\\webdriver\\remote\\remote_connection.py\", line 397, in _request\n    resp = self._conn.request(method, url, body=body, headers=headers)\n  File \"d:\\python37\\lib\\site-packages\\urllib3\\request.py\", line 72, in request\n    **urlopen_kw)\n  File \"d:\\python37\\lib\\site-packages\\urllib3\\request.py\", line 150, in request_encode_body\n    return self.urlopen(method, url, **extra_kw)\n  File \"d:\\python37\\lib\\site-packages\\urllib3\\poolmanager.py\", line 326, in urlopen\n    response = conn.urlopen(method, u.request_uri, **kw)\n  File \"d:\\python37\\lib\\site-packages\\urllib3\\connectionpool.py\", line 670, in urlopen\n    **response_kw)\n  File \"d:\\python37\\lib\\site-packages\\urllib3\\connectionpool.py\", line 670, in urlopen\n    **response_kw)\n  File \"d:\\python37\\lib\\site-packages\\urllib3\\connectionpool.py\", line 670, in urlopen\n    **response_kw)\n  File \"d:\\python37\\lib\\site-packages\\urllib3\\connectionpool.py\", line 641, in urlopen\n    _stacktrace=sys.exc_info()[2])\n  File \"d:\\python37\\lib\\site-packages\\urllib3\\util\\retry.py\", line 399, in increment\n    raise MaxRetryError(_pool, url, error or ResponseError(cause))\n"}, "start": 1587116111394, "stop": 1587116116534}], "start": 1587116111394, "stop": 1587116119144}