{"uuid": "b5fa3f4e-af45-42fa-b5cd-9ddcfe62edd4", "children": ["17856abc-ce17-46a8-baa9-1844c7ac1045", "919675ab-67ba-4132-95ec-d002d2f8df8e", "81756f5e-7ecc-41b9-b4ba-7f36f925b989", "cbe78243-23cb-4f52-93c6-067b37038e06", "f2a183ea-83c0-4781-badd-b737b09419f1", "04bb8d3b-2e9d-4eab-8dc1-6826ed8150f2", "361d5a31-2622-4084-a626-beb8ad126d4a"], "befores": [{"name": "driver", "status": "broken", "statusDetails": {"message": "urllib3.exceptions.MaxRetryError: HTTPConnectionPool(host='127.0.0.1', port=4723): Max retries exceeded with url: /wd/hub/session (Caused by NewConnectionError('<urllib3.connection.HTTPConnection object at 0x0000013B444099C8>: Failed to establish a new connection: [WinError 10061] 由于目标计算机积极拒绝，无法连接。'))\n", "trace": "  File \"d:\\python37\\lib\\site-packages\\pluggy\\callers.py\", line 187, in _multicall\n    res = hook_impl.function(*args)\n  File \"d:\\python37\\lib\\site-packages\\_pytest\\fixtures.py\", line 958, in pytest_fixture_setup\n    result = call_fixture_func(fixturefunc, request, kwargs)\n  File \"d:\\python37\\lib\\site-packages\\_pytest\\fixtures.py\", line 784, in call_fixture_func\n    res = next(it)\n  File \"D:\\Atest_project\\appium_pytest_tea7\\test_case\\conftest.py\", line 38, in driver\n    driver = webdriver.Remote('http://' + str(data['ip']) + ':' + str(data['port']) + '/wd/hub', desired_caps)\n  File \"d:\\python37\\lib\\site-packages\\appium\\webdriver\\webdriver.py\", line 151, in __init__\n    proxy\n  File \"d:\\python37\\lib\\site-packages\\selenium\\webdriver\\remote\\webdriver.py\", line 157, in __init__\n    self.start_session(capabilities, browser_profile)\n  File \"d:\\python37\\lib\\site-packages\\appium\\webdriver\\webdriver.py\", line 227, in start_session\n    response = self.execute(RemoteCommand.NEW_SESSION, parameters)\n  File \"d:\\python37\\lib\\site-packages\\selenium\\webdriver\\remote\\webdriver.py\", line 319, in execute\n    response = self.command_executor.execute(driver_command, params)\n  File \"d:\\python37\\lib\\site-packages\\selenium\\webdriver\\remote\\remote_connection.py\", line 374, in execute\n    return self._request(command_info[0], url, body=data)\n  File \"d:\\python37\\lib\\site-packages\\selenium\\webdriver\\remote\\remote_connection.py\", line 397, in _request\n    resp = self._conn.request(method, url, body=body, headers=headers)\n  File \"d:\\python37\\lib\\site-packages\\urllib3\\request.py\", line 72, in request\n    **urlopen_kw)\n  File \"d:\\python37\\lib\\site-packages\\urllib3\\request.py\", line 150, in request_encode_body\n    return self.urlopen(method, url, **extra_kw)\n  File \"d:\\python37\\lib\\site-packages\\urllib3\\poolmanager.py\", line 326, in urlopen\n    response = conn.urlopen(method, u.request_uri, **kw)\n  File \"d:\\python37\\lib\\site-packages\\urllib3\\connectionpool.py\", line 670, in urlopen\n    **response_kw)\n  File \"d:\\python37\\lib\\site-packages\\urllib3\\connectionpool.py\", line 670, in urlopen\n    **response_kw)\n  File \"d:\\python37\\lib\\site-packages\\urllib3\\connectionpool.py\", line 670, in urlopen\n    **response_kw)\n  File \"d:\\python37\\lib\\site-packages\\urllib3\\connectionpool.py\", line 641, in urlopen\n    _stacktrace=sys.exc_info()[2])\n  File \"d:\\python37\\lib\\site-packages\\urllib3\\util\\retry.py\", line 399, in increment\n    raise MaxRetryError(_pool, url, error or ResponseError(cause))\n"}, "start": 1587116157834, "stop": 1587116162874}], "start": 1587116157834, "stop": 1587116165569}